Workbook

Sheet Vonat
B1: Düsledorf - Bécs | C1: Bécs - Düsledorf | D1: Düsledorf - Bécs | E1: Bécs - Düsledorf | F1: Düsledorf - Bécs | G1: Bécs - Düsledorf | H1: -
A2: SEPTEMBER
B4: Hétfő | C4: Kedd | D4: Szerda | E4: Csütörtök | F4: Péntek | G4: Szombat | H4: Vasárnap
A5: … Week 35 | D5: 1 | E5: 2 | F5: 3 | G5: 4 | H5: 5
A6: Week 36 | B6: 6 | C6: 7 | D6: 8 | E6: 9 | F6: 10 | G6: 11 | H6: 12
A7: Week 37 | B7: HÉTFŐI VONATOT MINDÍG 12 RE VISZZÜK a 16 H OOSTRUMI LERAKÓ MIATT | C7: 14 | D7: 15 | E7: 16 Viszi:PTT 809 Nagy György Feladja:XVV-488 Elhozza:WDR-823 | F7: 17 Viszi: PTT-811 Fodor Károly Feladja:WFP-446 Elhozza:XVV-488 | G7: 18 Viszi:Hangyál Gábor, Hétfőn elhozza , WIttman ( wfp ) Feladja:WAZ 645 Elhozza:WFP-446 | H7: SZOMBATON A LEADÁS 9 RE MENJEN !!!!
A8: Week 38 | B8: 20 Viszi:LAjkó Feladja:XYE-502 Elhozza:WAZ645 | C8: 21 Viszi: Leskó NUC 259 Feladja:WDR 825 Elhozza:XYE-502 | D8: 22 Viszi:Desics Lacibá NLF 971 Feladja:WFP 443 Elhozza:WDR 825 | E8: 23 Viszi:WITTMAN Feladja:WAB 569 Elhozza:WFP 443 | F8: 24 Viszi:NLF 970 Feladja:XYY 027 Elhozza:WAB 569 | G8: 25 Viszi:Wittman Feladja:XVV 489 Elhozza:XYY-027 | H8: SZOMBATON A LEADÁS 9 RE MENJEN !!!!
A9: Week 39 ... | B9: 27 Viszi:Lakatos Feladja:XYN 563 Elhozza:XVV 489 | C9: 28 Viszi: Rózsa A. NJR 106 Feladja: XYY 030 Elhozza: XYN 563 | D9: 29 Viszi: Sütő K. SPP 790 Feladja:WFP 448 Elhozza: XYY 030 | E9: 30 Viszi:Wittman Feladja:XYN-571 Elhozza:WFP 448 | H9: SZOMBATON A LEADÁS 9 RE MENJEN !!!!
A10: SEPTEMBER TOTAL:
A11: OCTOBER
B13: Monday | C13: Tuesday | D13: Wednesday | E13: Thursday | F13: Friday | G13: Saturday | H13: Sunday
A14: … Week 39 | B14: HÉTFŐI VONATOT MINDÍG 12 RE VISZZÜK a 16 H OOSTRUMI LERAKÓ MIATT | F14: 1 Viszi:Balázs István RKG 682 Feladja:WFP 447 Elhozza:XYN-571 | G14: 2 Viszi:Wittman Feladja:WFP 445 Elhozza:WFP 447 | H14: SZOMBATON A LEADÁS 9 RE MENJEN !!!!
A15: Week 40 | B15: 4 Viszi:Lacibá Feladja:WAB569 Elhozza:WFP 445 | C15: 5 Viszi:RÓZSA Feladja:WFP-444 Elhozza:WAB 569 | D15: 6 Viszi: Nagy tamás Feladja:WDR 821 Elhozza:WFP444 | E15: 7 Viszi: pjp 383 lászló lajos Feladja:WDR-824 Elhozza:WDR 821 | F15: 8 Viszi:Pázmándi Feladja:XYE 502 Elhozza:WDR-824 | G15: 9 Viszi:Wittman Feladja:Waz 632 Elhozza:XYE-502 | H15: SZOMBATON A LEADÁS 9 RE MENJEN !!!!
A16: Week 41 | B16: 11 Viszi: Feladja:WFP445 Elhozza:Waz 632 | C16: 12 Viszi:Rózsa , Fodor Feladja:XYY026, WAB 562 Elhozza:WFP 445 | D16: 13 Viszi:pÁLFI FENYVESI Feladja:Wab570 WDR 820 Elhozza:XYY 026, WAB 562 | E16: 14 Viszi: WITTMAN Feladja:waz633 Elhozza:WAB 570 | F16: 15 Viszi:fodor károly Feladja:XVV 488 Elhozza:WAZ 633 | G16: 16 Viszi:WITTMANN Feladja:xzg 404 Elhozza:XVV 488 | H16: SZOMBATON A LEADÁS 9 RE MENJEN !!!!
A17: Week 42 | B17: 18 Viszi:Lakatos Feladja:WFP 441 Elhozza:XZG 404 | C17: 19 Viszi:nagy tamás , slebársky Feladja:WAB 570 xzv990 Elhozza:WFP 441 | D17: 20 Viszi:hanzi hrasztics Feladja:WFP443 Elhozza:Wab 570 xzv 990 | E17: 21 Viszi: Wittman Feladja:WDR 827 Elhozza:WFP 443 | F17: 22 Viszi:Nagy tomi Feladja:WAZ 632 wbn 286 fodor Elhozza:WDR 827 | G17: 23 | H17: SZOMBATON A LEADÁS 9 RE MENJEN !!!!
A18: Week 43 | B18: 25 Viszi:Wittman Feladja: Elhozza:WAZ 632 wbn 286 | C18: 26 | D18: 27 | E18: 28 | F18: 29 | G18: 30 | H18: SZOMBATON A LEADÁS 9 RE MENJEN !!!!
A19: OCTOBER TOTAL:
A20: NOVEMBER
B22: Monday | C22: Tuesday | D22: Wednesday | E22: Thursday | F22: Friday | G22: Saturday | H22: Sunday
A23: Week 44 | B23: HÉTFŐI VONATOT MINDÍG 12 RE VISZZÜK a 16 H OOSTRUMI LERAKÓ MIATT | C23: 2 | D23: 3 | E23: 4 Viszi:Wittman Feladja:Xzg 404 Elhozza: | F23: 5 Viszi:Nagy Tomi Feladja:Wfp 443 Elhozza:Xzg 404 | G23: 6 Viszi: Wittman Feladja: WDR 820 + XZV 988 Elhozza:Wfp 443 | H23: HÉTFŐI VONATOT MINDÍG 12 RE VISZZÜK a 16 H OOSTRUMI LERAKÓ MIATT | I23: SZOMBATON A LEADÁS 9 RE MENJEN !!!!
A24: Week 45 | B24: 8 Viszi:Lakatos , Hideg Atilla Feladja: XYY 026 + WAB 566 Elhozza:Wdr820 + xzv 988 | C24: 9 Viszi: Heizer, Fodor K. Feladja:XZG 406 + WBJ 961 Elhozza:xyy 026- wab 566 | D24: 10 Viszi:Szabó zoli, leskó zoltán Feladja:waz 632 wcr 369 Elhozza:Xzg 406- wbn 294 | E24: 11 Viszi: Wittmann B + Feladja: WAB 569 + WDJ 918 Elhozza:WFP442+ WCR369 | F24: 12 Viszi: Wittmann B Feladja: WAB 567+ Elhozza: | G24: 13 Viszi: Feladja: Elhozza: | H24: SZOMBATON A LEADÁS 9 RE MENJEN !!!!
A25: Week 46 | B25: 15 Viszi: Heizer Feladja: xyy 027 Elhozza: | C25: 16 Viszi:Fodor zsolt, Slebárszky Feladja: ,wct 773 xzg 403 Elhozza:xzv 974, xyy 027 | D25: 17 Viszi:Hanzi ,nagy györgy Feladja:XZV 987, WBN 286 Elhozza: wct 773 xzg 403 | E25: 18 Viszi: Wittmann, Dalanics Feladja: WDR 827, WDJ 962 Elhozza:XZV 987,WBN 286 | F25: 19 Viszi:Bálint László,Vancsó Feladja:wdr 826 WBN 291 Elhozza:WDR 827 ,WDJ 962 | G25: 20 Viszi:wittman , Ormándi Feladja:WAB 751 ,wdr 824 Elhozza:WDR 826,wbn 291 | H25: SZOMBATON A LEADÁS 9 RE MENJEN !!!!
A26: Week 47 | B26: 22 Viszi: Nagy Tamás Molárovits Feladja:XZG 401, wcr373 Elhozza:Wab 751 wdr 824 | C26: 23 Viszi:Farkas Rdolf , Rózsa Ati Feladja: XYN 571 , wdr826 Elhozza: XZG401 WCr 373 , | D26: 24 Viszi:Dénes Gábor, lajkó Feladja:Wab 567 , WBN288 Elhozza:XYN 571, wdr 826 | E26: 25 Viszi:Wittman Balázs , Balázs István Feladja: XZV 987 + WFP 447 Elhozza:WAB 567 , WBN 288 | F26: 26 Viszi: Tóth Zoli Farkas rudi Feladja:WAB-752 + XYY-029 Elhozza:Xzv 987 WFP 447 | G26: 27 Viszi: Perényi , Fodor karcsi Feladja: WAZ 638 / WDR 824 Elhozza:Wab 752+ xyy029 | H26: SZOMBATON A LEADÁS 9 RE MENJEN !!!!
A27: Week 48 … | B27: 29 Viszi:Szakács, Farkas Rudi Feladja:waz 634 , Wfp 447 Elhozza:Waz 638 + Wdr 824 | C27: 30 Viszi:Lázár gabi , Éliás attila Feladja:WAZ 645 / WDJ 960 Elhozza:waz 634, , Wab 752 | D27: WFP 447 szerdan jön le | H27: SZOMBATON A LEADÁS 9 RE MENJEN !!!!
A28: NOVEMBER TOTAL:
A29: DECEMBER
B31: Monday | C31: Tuesday | D31: Wednesday | E31: Thursday | F31: Friday | G31: Saturday | H31: Sunday
A32: … Week 48 | B32: HÉTFŐI VONATOT MINDÍG 12 RE VISZZÜK a 16 H OOSTRUMI LERAKÓ MIATT | C32: waz 624 | D32: 1 Viszi:, Dénes gabi , Nagy László Feladja:WFP 447 , WFP 443 ,WBU 760 Elhozza:WAZ 645 / WDJ 960 | E32: 2 Viszi:Wittman , tozsó Feladja:waz 638, WAB 567 Elhozza:WFP 447 , WFP 443 ,WBU 760 | F32: 3 Viszi:Heizer , pázmándi Feladja:Waz 641 XZG 401 Elhozza:wab 567 Waz 638 | G32: 4 Viszi:Wittman , Feladja:xzv 971, Wab 569 Elhozza:Waz 641 XZG 401 | H32: SZOMBATON A LEADÁS 9 RE MENJEN !!!!
A33: Week 49 | B33: 6 Viszi:Dalanics , Dalanics / Leiner Feladja:XZV 971,WFP 446 Elhozza:xzv 971, Wab 569 | C33: 7 Viszi:Wittman, karesz ,glázer Feladja:Wbn 287 waz 624, Elhozza:XZV 971,WFP 446 | D33: 8 Viszi:nagy tomi , leskó Feladja: wdr 820 ,WCU 058 Elhozza:Wbn 287 waz 624, | E33: 9 Viszi:Nagy györgy Wittman Feladja:wab 569 , WBN 290 Elhozza:wdr 820 ,WCU 058 | F33: 10 Viszi:Kovács ferenc , Farkas Rudolf Feladja:XYN 563,XZV 975 Elhozza: WBN 290 wab 569 , | G33: 11 Viszi:Witmman, Feladja:XZV 978,wdr 826 Elhozza:XYN 563,XZV 975 | H33: SZOMBATON A LEADÁS 9 RE MENJEN !!!!
A34: Week 50 | B34: 13 Viszi:Lakatos , Hideg Feladja:WCT 770,WFP 448 Elhozza: wdr 826 XZV 978, | C34: 14 Viszi:Nagy Tomi , Rózsa Feladja:WBN 294,WFp 444 Elhozza:WCT 770,WFP 448 | D34: 15 Viszi:hanzi , Kaona gábor Feladja:XZG 402,WDR 824 Elhozza:WBN 294,WFp 444 | E34: 16 Viszi:Kiss sanyi , németh zsolt Feladja:WFP 446,WAW 563 Elhozza:XZG 402,WDR 824 | F34: 17 Viszi:nagy tomi , leskó Feladja:WFP 441,WDJ 919 Elhozza:WFP 446,WAW 563 | G34: 18 Viszi:papp zoli, csicsai Feladja:xzv 978, xzv 990 Elhozza:WFP 441,WDJ 919 | H34: SZOMBATON A LEADÁS 9 RE MENJEN !!!!
A35: Week 51 | B35: 20 Viszi:NAgy szilárd Feladja:WAB 571,XZV 978 Elhozza:xzv 978, xzv 990 | C35: VÉÉÉGEEEEEEE | D35: 22 | E35: 23 | F35: Foglaláls leadni Január 8 ??? | G35: 25 | H35: SZOMBATON A LEADÁS 9 RE MENJEN !!!!
A36: Week 52 | B36: 27 | C36: 28 | D36: 29 | E36: 30 | F36: 31 | H36: SZOMBATON A LEADÁS 9 RE MENJEN !!!!
A40: 2022 JANUARY
B42: Monday | C42: Tuesday | D42: Wednesday | E42: Thursday | F42: Friday | G42: Saturday | H42: Sunday | I42: SZOMBATON A LEADÁS 9 RE MENJEN !!!!
A43: … Week 52 | B43: HÉTFŐI VONATOT MINDÍG 12 RE VISZZÜK a 16 H OOSTRUMI LERAKÓ MIATT | G43: 1 | H43: 2 | I43: SZOMBATON A LEADÁS 9 RE MENJEN !!!!
A44: Week 1 | B44: 3 FIRST TRAIN!! (planned) | C44: 4 | D44: 5 NO TRAIN! | E44: 6 (Epiphany Holiday) NO TRAIN! Düsseldorf: ? Vienna: CLOSED | F44: 7 FIRST TRAIN!! (planned) | G44: 8 Viszi:Wittmann Feladja: Waw 565,xyy026,wct772 Elhozza:- | H44: 9 | I44: SZOMBATON A LEADÁS 9 RE MENJEN !!!!
A45: Week 2 | B45: 10 Viszi:Simonka, Segedi ZSolt Feladja:wfp445 waw565wab566, Elhozza: Waw 565,wct772,xyy026 | C45: 11 Viszi:KovácsMarci, Kálóczi, Németh zsolt Feladja: WCU054 WAB 563 XYY 028 Elhozza:wfp445waw565wab566 | D45: 12 Viszi:Szalai,Hrasztics,fari rudi Feladja:WAZ 624,XYY 027 ,XZV 973 Elhozza:WCU054 WAB 563 XYY 028 | E45: 13 Viszi:CSicsai,Pollák,Perényi Feladja:WCU053,WCT773,WBN289 Elhozza:WAZ 624,xyy 027,XZV 973 | F45: 14 Viszi:Vancsó,Fenyvesi,Kálóczy Feladja: WCZ448,WCR370,XZG406 Elhozza:WCU053,WCT773,WBN289 | G45: 15 Viszi:Éliás, Simon,Lázár Feladja: XZV972,XYY029,XZV983 Elhozza:WCZ448,WCR370,XZG406 | H45: 16 | I45: SZOMBATON A LEADÁS 9 RE MENJEN !!!!
A46: Week 3 | B46: 17 Viszi:Fodor, Nagy L ,Szalai Feladja: WFR663,XZG 403,WDR824 Elhozza:XZV972,XYY029,XZV983 | C46: 18 Viszi:Dénes , Záreczki, Sinkovits Feladja: WAB 567,XZV977,WDJ957 Elhozza:WFR663,XZG 403,WCZ443 | D46: 19 Viszi:Szalai, Kovács F ,Fodor K Feladja:XZV972,WAB 569,WCU 059 Elhozza: WAB567,XZV977,WDJ957 | E46: 20 Viszi:Wittman, tozsó, Nagy Laci Feladja: WAW565,WDR824,wab570 Elhozza:XZV972,WAB 569,WCU 059 | F46: 21 Viszi:Tóth zoltán , Láncz Lakatos Feladja: XZG 405 ,WBN294 Elhozza:WAW565,WDR824,wab570 | G46: 22 Viszi:Wittmann, Leiner Feladja: WCU 054,WDR821,WFP443 Elhozza:XZG 405 ,WBN294 | H46: 23 | I46: SZOMBATON A LEADÁS 9 RE MENJEN !!!!
A47: Week 4 | B47: 24 Viszi:gerstmayer ,Desics,Simonka Feladja: WCU 057,WAW 565,XYN 564 Elhozza:WCU054,WDR821,WFP443 | C47: 25 Viszi:Záreczki, baké,sinkovits Feladja: WBU760,XZV977,WFP442 Elhozza:WCU 057, WAW565,XYN 564 | D47: 26 Viszi:Fraksa rudolf,Kozma,Bakán Feladja: WAW564,WDR821,WBN289 Elhozza:WBU760,XZV977,WFP442 | E47: 27 Viszi:Wittman,kántor,záreczki Feladja: WDR827WCZ 449 WAW 569 Elhozza:WAW564,WDR821,WBN289 | F47: 28 Viszi:Kov Márton, lakatos , horváth i Feladja: xzg407,WDR820,WAZ641 Elhozza:WDR827WCZ 449 WAW 569 | G47: 29 Viszi:Wittman,Bálint László,Szabó Z Feladja: Wbn288,WDR 823,WAZ 642 Elhozza:xzg407,WDR820,WAZ641 | H47: 30 | I47: SZOMBATON A LEADÁS 9 RE MENJEN !!!!
A48: Week 5 | B48: 31 Viszi:Nagy L,Heizer,Dalanics Feladja: XYY 029,WCR 370,XZV 985 Elhozza:Wbn288,WDR 823,WAZ 642
...

Sheet Szabik 2021
A1: 2022 | B1: X -et rakj abba a cellába, ahol szabadságot akarsz rögzíteni!!
B2: ezt ne piszkáld | C2: ezt se | D2: ezt se | E2: ezt se | F2: SZ | G2: CS | H2: P | I2: SZ | J2: V | K2: H | L2: K | M2: SZ | N2: CS | O2: P | P2: SZ | Q2: V | R2: H | S2: K | T2: SZ | U2: CS | V2: P | W2: SZ | X2: V | Y2: H | Z2: K | AA2: SZ | AB2: CS | AC2: P | AD2: SZ | AE2: V | AF2: H | AG2: K | AH2: SZ | AI2: CS | AJ2: P | AK2: SZ | AL2: V | AM2: H | AN2: K | AO2: SZ | AP2: CS | AQ2: P | AR2: SZ | AS2: V | AT2: H | AU2: K | AV2: SZ | AW2: CS | AX2: P | AY2: SZ | AZ2: V | BA2: H | BB2: K | BC2: SZ | BD2: CS | BE2: P | BF2: SZ | BG2: V | BH2: H | BI2: K | BJ2: SZ | BK2: CS | BL2: P | BM2: SZ | BN2: V | BO2: H | BP2: K | BQ2: SZ | BR2: CS | BS2: P | BT2: SZ | BU2: V | BV2: H | BW2: K | BX2: SZ | BY2: CS | BZ2: P | CA2: SZ | CB2: V | CC2: H | CD2: K | CE2: SZ | CF2: CS | CG2: P | CH2: SZ | CI2: V | CJ2: H | CK2: K | CL2: SZ | CM2: CS | CN2: P | CO2: SZ | CP2: V | CQ2: H | CR2: K | CS2: SZ | CT2: CS | CU2: P | CV2: SZ | CW2: V | CX2: H | CY2: K | CZ2: SZ | DA2: CS | DB2: P | DC2: SZ | DD2: V | DE2: H | DF2: K | DG2: SZ | DH2: CS | DI2: P | DJ2: SZ | DK2: V | DL2: H | DM2: K | DN2: SZ | DO2: CS | DP2: P | DQ2: SZ | DR2: V | DS2: H | DT2: K | DU2: SZ | DV2: CS | DW2: P
A3: Név | B3: Összes kivehető Szabadság | C3: Még felhasználható szabadság (augusztus végi állapot alapján) | D3: Szept 1-től igénybe vett | E3: Marad | F3: 01.szept | G3: 02.szept | H3: 03.szept | I3: 04.szept | J3: 05.szept | K3: 06.szept | L3: 07.szept | M3: 08.szept | N3: 09.szept | O3: 10.szept | P3: 11.szept | Q3: 12.szept | R3: 13.szept | S3: 14.szept | T3: 15.szept | U3: 16.szept | V3: 17.szept | W3: 18.szept | X3: 19.szept | Y3: 20.szept | Z3: 21.szept | AA3: 22.szept | AB3: 23.szept | AC3: 24.szept | AD3: 25.szept | AE3: 26.szept | AF3: 27.szept | AG3: 28.szept | AH3: 29.szept | AI3: 30.szept | AJ3: 01.okt | AK3: 02.okt | AL3: 03.okt | AM3: 04.okt | AN3: 05.okt | AO3: 06.okt | AP3: 07.okt | AQ3: 08.okt | AR3: 09.okt | AS3: 10.okt | AT3: 11.okt | AU3: 12.okt | AV3: 13.okt | AW3: 14.okt | AX3: 15.okt | AY3: 16.okt | AZ3: 17.okt | BA3: 18.okt | BB3: 19.okt | BC3: 20.okt | BD3: 21.okt | BE3: 22.okt | BF3: 23.okt | BG3: 24.okt | BH3: 25.okt | BI3: 26.okt | BJ3: 27.okt | BK3: 28.okt | BL3: 29.okt | BM3: 30.okt | BN3: 31.okt | BO3: 01.nov | BP3: 02.nov | BQ3: 03.nov | BR3: 04.nov | BS3: 05.nov | BT3: 06.nov | BU3: 07.nov | BV3: 08.nov | BW3: 09.nov | BX3: 10.nov | BY3: 11.nov | BZ3: 12.nov | CA3: 13.nov | CB3: 14.nov | CC3: 15.nov | CD3: 16.nov | CE3: 17.nov | CF3: 18.nov | CG3: 19.nov | CH3: 20.nov | CI3: 21.nov | CJ3: 22.nov | CK3: 23.nov | CL3: 24.nov | CM3: 25.nov | CN3: 26.nov | CO3: 27.nov | CP3: 28.nov | CQ3: 29.nov | CR3: 30.nov | CS3: 01.dec | CT3: 02.dec | CU3: 03.dec | CV3: 04.dec | CW3: 05.dec | CX3: 06.dec | CY3: 07.dec | CZ3: 08.dec | DA3: 09.dec | DB3: 10.dec | DC3: 11.dec | DD3: 12.dec | DE3: 13.dec | DF3: 14.dec | DG3: 15.dec | DH3: 16.dec | DI3: 17.dec | DJ3: 18.dec | DK3: 19.dec | DL3: 20.dec | DM3: 21.dec | DN3: 22.dec | DO3: 23.dec | DP3: 24.dec | DQ3: 25.dec | DR3: 26.dec | DS3: 27.dec | DT3: 28.dec | DU3: 29.dec | DV3: 30.dec | DW3: 31.dec
A4: Adamek István | B4: 30 | C4: 11 | D4: =COUNTIF(F4:DW4,"x") -> 16 | E4: =C4-D4 -> -5 | BK4: x | BL4: x | DJ4: x | DK4: x | DL4: x | DM4: x | DN4: x | DO4: x | DP4: x | DQ4: x | DR4: x | DS4: x | DT4: x | DU4: x | DV4: x | DW4: x | DX4: JAN 2- indulás
A5: Árvai József | B5: 33 | C5: 10 | D5: =COUNTIF(F5:DW5,"x") -> 4 | E5: =C5-D5 -> 6 | AX5: X | DU5: x | DV5: x | DW5: x | DX5: 27-28 DSV, Jan 2 kezdés
A6: Bagi Lajos | B6: 30 | C6: 14 | D6: =COUNTIF(F6:DW6,"x") -> 9 | E6: =C6-D6 -> 5 | DL6: x | DM6: x | DN6: x | DO6: x | DS6: x | DT6: x | DU6: x | DV6: x | DW6: x | DX6: Indulnak amikor kell
A7: Bagi Márió Lajos | B7: 22 | C7: 9 | D7: =COUNTIF(F7:DW7,"x") -> 9 | E7: =C7-D7 -> 0 | DL7: x | DM7: x | DN7: x | DO7: x | DS7: x | DT7: x | DU7: x | DV7: x | DW7: x | DX7: Indulnak amikor kell
A8: Bak László | B8: 30 | C8: 14 | D8: =COUNTIF(F8:DW8,"x") -> 9 | E8: =C8-D8 -> 5 | DL8: x | DM8: x | DN8: x | DO8: x | DS8: x | DT8: x | DU8: x | DV8: x | DW8: x | DX8: Jan 3-4 indulnak ahogy lesz munka
A9: Bakán Tibor | B9: 30 | C9: 6 | D9: =COUNTIF(F9:DW9,"x") -> 14 | E9: =C9-D9 -> -8 | CG9: x | CJ9: x | CK9: x | CL9: x | CM9: x | CN9: x | CQ9: x | CR9: x | CS9: x | DS9: x | DT9: x | DU9: x | DV9: x | DW9: x | DX9: JAN 2- indulás
A10: Balázs István | B10: 31 | C10: 21 | D10: =COUNTIF(F10:DW10,"x") -> 10 | E10: =C10-D10 -> 11 | DI10: x | DL10: x | DM10: x | DN10: x | DO10: x | DS10: x | DT10: x | DU10: x | DV10: x | DW10: x | DX10: JAN 2- indulás
A11: Balázs Tibor | B11: 30 | C11: 15 | D11: =COUNTIF(F11:DW11,"x") -> 14 | E11: =C11-D11 -> 1 | AD11: x | AE11: x | BE11: x | BF11: x | BG11: x | BH11: x | BM11: x | BN11: x | BO11: x | DS11: x | DT11: x | DU11: x | DV11: x | DW11: x | DX11: JAN 2- indulás
A12: Bálint László | B12: 24 | C12: 6 | D12: =COUNTIF(F12:DW12,"x") -> 6 | E12: =C12-D12 -> 0 | BV12: x | DS12: x | DT12: x | DU12: x | DV12: x | DW12: x | DX12: JAN 5- indulás
A13: Beke Zsolt | B13: 34 | C13: 15 | D13: =COUNTIF(F13:DW13,"x") -> 0 | E13: =C13-D13 -> 15
A14: Csák László | B14: 30 | C14: 18 | D14: =COUNTIF(F14:DW14,"x") -> 8 | E14: =C14-D14 -> 10 | BE14: x | DN14: x | DO14: x | DS14: x | DT14: x | DU14: x | DV14: x | DW14: x | DX14: JAN 3-4- indulás
A15: Cselényi József | B15: 31 | C15: 20 | D15: =COUNTIF(F15:DW15,"x") -> 0 | E15: =C15-D15 -> 20
A16: Csicsai Gábor | B16: 30 | C16: 11 | D16: =COUNTIF(F16:DW16,"x") -> 11 | E16: =C16-D16 -> 0 | BL16: x | BO16: x | DL16: x | DM16: x | DN16: x | DO16: x | DS16: x | DT16: x | DU16: x | DV16: x | DW16: x | DX16: JAN 2- indulás
A17: Dalanics Zsolt | B17: 30 | C17: 21 | D17: =COUNTIF(F17:DW17,"x") -> 7 | E17: =C17-D17 -> 14 | DN17: x | DO17: x | DS17: x | DT17: x | DU17: x | DV17: x | DW17: x | DX17: JAN 2- indulás
A18: Dallos Zoltán János | B18: 30 | C18: 7 | D18: =COUNTIF(F18:DW18,"x") -> 6 | E18: =C18-D18 -> 1 | DO18: x | DS18: x | DT18: x | DU18: x | DV18: x | DW18: x | DX18: 3-JAN indulás
A19: Dani Sándor | B19: 30 | C19: 17 | D19: =COUNTIF(F19:DW19,"x") -> 0 | E19: =C19-D19 -> 17
A20: Dénes Gábor | B20: 22 | C20: 6 | D20: =COUNTIF(F20:DW20,"x") -> 9 | E20: =C20-D20 -> -3 | DL20: x | DM20: x | DN20: x | DO20: x | DS20: x | DT20: x | DU20: x | DV20: x | DW20: x | DX20: JAN 5- indulás
A21: Desics László | B21: 30 | C21: 3 | D21: =COUNTIF(F21:DW21,"x") -> 0 | E21: =C21-D21 -> 3
A22: Drozd Péter | B22: 30 | C22: 2 | D22: =COUNTIF(F22:DW22,"x") -> 5 | E22: =C22-D22 -> -3 | DS22: x | DT22: x | DU22: x | DV22: x | DW22: x | DX22: JAN 4- este indulna, de még egyezteteni
A23: Eipl András | B23: 32 | C23: 23 | D23: =COUNTIF(F23:DW23,"x") -> 0 | E23: =C23-D23 -> 23
A24: Éliás Attila | B24: 32 | C24: 14 | D24: =COUNTIF(F24:DW24,"x") -> 6 | E24: =C24-D24 -> 8 | DE24: x | DS24: x | DT24: x | DU24: x | DV24: x | DW24: x | DX24: JAN 5- indulás
A25: Ércz József | B25: 32 | C25: 4 | D25: =COUNTIF(F25:DW25,"x") -> 6 | E25: =C25-D25 -> -2 | AX25: X | DS25: x | DT25: x | DU25: x | DV25: x | DW25: x | DX25: JAN 3 belföld, JAN 4 indulás
A26: Falusi Ferenc Sándor | B26: 30 | C26: 6 | D26: =COUNTIF(F26:DW26,"x") -> 5 | E26: =C26-D26 -> 1 | DS26: x | DT26: x | DU26: x | DV26: x | DW26: x | DX26: JAN 4- indulás
A27: Farkas Attila | B27: 30 | C27: 18 | D27: =COUNTIF(F27:DW27,"x") -> 0 | E27: =C27-D27 -> 18
A28: Farkas Bálint | B28: 8 | C28: 5 | D28: =COUNTIF(F28:DW28,"x") -> 0 | E28: =C28-D28 -> 5
A29: Farkas Rudolf Attila | B29: 30 | C29: 4 | D29: =COUNTIF(F29:DW29,"x") -> 13 | E29: =C29-D29 -> -9 | AO29: x | AP29: x | BM29: x | BN29: x | BO29: x | DO29: x | DQ29: x | DR29: x | DS29: x | DT29: x | DU29: x | DV29: x | DW29: x | DX29: JAN 3- indulás
A30: Fehér Imre | B30: 30 | C30: 12 | D30: =COUNTIF(F30:DW30,"x") -> 20 | E30: =C30-D30 -> -8 | AT30: x | AU30: x | AV30: x | AW30: x | AX30: x | AY30: x | AZ30: x | BA30: x | BB30: x | BC30: x | BD30: x | BE30: x | BF30: x | BG30: x | DO30: x | DS30: x | DT30: x | DU30: x | DV30: x | DW30: x | DX30: JAN 10 kezdés
A31: Fehér Róbert | B31: 22 | C31: 4 | D31: =COUNTIF(F31:DW31,"x") -> 20 | E31: =C31-D31 -> -16 | AT31: x | AU31: x | AV31: x | AW31: x | AX31: x | AY31: x | AZ31: x | BA31: x | BB31: x | BC31: x | BD31: x | BE31: x | BF31: x | BG31: x | DO31: x | DS31: x | DT31: x | DU31: x | DV31: x | DW31: x | DX31: JAN 10 kezdés
A32: Fenyvesi Zsolt | B32: 30 | C32: 0 | D32: =COUNTIF(F32:DW32,"x") -> 1 | E32: =C32-D32 -> -1 | BE32: x | DX32: 2 ünnep között ki, Jan 1-12-ig szabi, 12-én reggel tud indulni
A33: Fodor Károly | B33: 30 | C33: 17 | D33: =COUNTIF(F33:DW33,"x") -> 5 | E33: =C33-D33 -> 12 | DS33: x | DT33: x | DU33: x | DV33: x | DW33: x | DX33: JAN 5- indulás, ha nincs munka akkor JAN 10
A34: Fodor Zsolt | B34: 30 | C34: 2 | D34: =COUNTIF(F34:DW34,"x") -> 5 | E34: =C34-D34 -> -3 | DS34: x | DT34: x | DU34: x | DV34: x | DW34: x | DX34: DEC 21-én lejár a jogsija, indulást egyeztetni
A35: Gárdonyi Tibor Zsolt | B35: 30 | C35: 2 | D35: =COUNTIF(F35:DW35,"x") -> 0 | E35: =C35-D35 -> 2
A36: Gerstmayer Zoltán | B36: 30 | C36: 4 | D36: =COUNTIF(F36:DW36,"x") -> 6 | E36: =C36-D36 -> -2 | CT36: x | DS36: x | DT36: x | DU36: x | DV36: x | DW36: x | DX36: JAN 3- indulás
A37: Gérus Elemér | B37: 35 | C37: 21 | D37: =COUNTIF(F37:DW37,"x") -> 0 | E37: =C37-D37 -> 21
A38: Giber Zoltán | B38: 34 | C38: 7 | D38: =COUNTIF(F38:DW38,"x") -> 7 | E38: =C38-D38 -> 0 | DN38: x | DO38: x | DS38: x | DT38: x | DU38: x | DV38: x | DW38: x | DX38: Ha kell akkor 31-én tud indulni
A39: Glázer János | B39: 31 | C39: 17 | D39: =COUNTIF(F39:DW39,"x") -> 7 | E39: =C39-D39 -> 10 | AM39: x | AN39: x | CK39: x | DT39: x | DU39: x | DV39: x | DW39: x | DX39: JAN 2- indulás
A40: Gonda Gergő | B40: 26 | C40: 19 | D40: =COUNTIF(F40:DW40,"x") -> 5 | E40: =C40-D40 -> 14 | DS40: x | DT40: x | DU40: x | DV40: x | DW40: x
...

Sheet ÉVVÉGE 2021
A1: Név | B1: Összes kivehető Szabadság | C1: Még felhasználható szabadság (augusztus végi állapot alapján) | D1: Szept 1-től igénybe vett | E1: Marad | F1: 13.dec | G1: 14.dec | H1: 15.dec | I1: 16.dec | J1: 17.dec | K1: 18.dec | L1: 19.dec | M1: 20.dec | N1: 21.dec | O1: 22.dec | P1: 23.dec | Q1: 24.dec | R1: 25.dec | S1: 26.dec | T1: 27.dec | U1: 28.dec | V1: 29.dec | W1: 30.dec | X1: 31.dec
A2: Adamek István | B2: 30 | C2: 11 | D2: =COUNTIF(F2:DW2,"x") -> 14 | E2: =C2-D2 -> -3 | K2: x | L2: x | M2: x | N2: x | O2: x | P2: x | Q2: x | R2: x | S2: x | T2: x | U2: x | V2: x | W2: x | X2: x | Y2: JAN 2- indulás
A3: Árvai József | B3: 33 | C3: 10 | D3: =COUNTIF(F3:DW3,"x") -> 3 | E3: =C3-D3 -> 7 | V3: x | W3: x | X3: x | Y3: 27-28 DSV, Jan 2 kezdés
A4: Bagi Lajos | B4: 30 | C4: 14 | D4: =COUNTIF(F4:DW4,"x") -> 9 | E4: =C4-D4 -> 5 | M4: x | N4: x | O4: x | P4: x | T4: x | U4: x | V4: x | W4: x | X4: x | Y4: Indulnak amikor kell
A5: Bagi Márió Lajos | B5: 22 | C5: 9 | D5: =COUNTIF(F5:DW5,"x") -> 9 | E5: =C5-D5 -> 0 | M5: x | N5: x | O5: x | P5: x | T5: x | U5: x | V5: x | W5: x | X5: x | Y5: Indulnak amikor kell
A6: Bak László | B6: 30 | C6: 14 | D6: =COUNTIF(F6:DW6,"x") -> 9 | E6: =C6-D6 -> 5 | M6: x | N6: x | O6: x | P6: x | T6: x | U6: x | V6: x | W6: x | X6: x | Y6: Jan 3-4 indulnak ahogy lesz munka
A7: Bakán Tibor | B7: 30 | C7: 6 | D7: =COUNTIF(F7:DW7,"x") -> 5 | E7: =C7-D7 -> 1 | T7: x | U7: x | V7: x | W7: x | X7: x | Y7: JAN 2- indulás
A8: Balázs István | B8: 31 | C8: 21 | D8: =COUNTIF(F8:DW8,"x") -> 10 | E8: =C8-D8 -> 11 | J8: x | M8: x | N8: x | O8: x | P8: x | T8: x | U8: x | V8: x | W8: x | X8: x | Y8: JAN 2- indulás
A9: Balázs Tibor | B9: 30 | C9: 15 | D9: =COUNTIF(F9:DW9,"x") -> 5 | E9: =C9-D9 -> 10 | T9: x | U9: x | V9: x | W9: x | X9: x | Y9: JAN 2- indulás
A10: Bálint László | B10: 24 | C10: 6 | D10: =COUNTIF(F10:DW10,"x") -> 5 | E10: =C10-D10 -> 1 | T10: x | U10: x | V10: x | W10: x | X10: x | Y10: JAN 5- indulás
A11: Beke Zsolt | B11: 34 | C11: 15 | D11: =COUNTIF(F11:DW11,"x") -> 0 | E11: =C11-D11 -> 15
A12: Csák László | B12: 30 | C12: 18 | D12: =COUNTIF(F12:DW12,"x") -> 7 | E12: =C12-D12 -> 11 | O12: x | P12: x | T12: x | U12: x | V12: x | W12: x | X12: x | Y12: JAN 3-4- indulás
A13: Cselényi József | B13: 31 | C13: 20 | D13: =COUNTIF(F13:DW13,"x") -> 0 | E13: =C13-D13 -> 20
A14: Csicsai Gábor | B14: 30 | C14: 11 | D14: =COUNTIF(F14:DW14,"x") -> 9 | E14: =C14-D14 -> 2 | M14: x | N14: x | O14: x | P14: x | T14: x | U14: x | V14: x | W14: x | X14: x | Y14: JAN 2- indulás
A15: Dalanics Zsolt | B15: 30 | C15: 21 | D15: =COUNTIF(F15:DW15,"x") -> 7 | E15: =C15-D15 -> 14 | O15: x | P15: x | T15: x | U15: x | V15: x | W15: x | X15: x | Y15: JAN 2- indulás
A16: Dallos Zoltán János | B16: 30 | C16: 7 | D16: =COUNTIF(F16:DW16,"x") -> 6 | E16: =C16-D16 -> 1 | P16: x | T16: x | U16: x | V16: x | W16: x | X16: x | Y16: 3-JAN indulás
A17: Dénes Gábor | B17: 22 | C17: 6 | D17: =COUNTIF(F17:DW17,"x") -> 9 | E17: =C17-D17 -> -3 | M17: x | N17: x | O17: x | P17: x | T17: x | U17: x | V17: x | W17: x | X17: x | Y17: JAN 5- indulás
A18: Desics László | B18: 30 | C18: 3 | D18: =COUNTIF(F18:DW18,"x") -> 0 | E18: =C18-D18 -> 3
A19: Drozd Péter | B19: 30 | C19: 2 | D19: =COUNTIF(F19:DW19,"x") -> 5 | E19: =C19-D19 -> -3 | T19: x | U19: x | V19: x | W19: x | X19: x | Y19: JAN 4- este indulna,
A20: Eipl András | B20: 32 | C20: 23 | D20: =COUNTIF(F20:DW20,"x") -> 0 | E20: =C20-D20 -> 23
A21: Éliás Attila | B21: 32 | C21: 14 | D21: =COUNTIF(F21:DW21,"x") -> 6 | E21: =C21-D21 -> 8 | F21: x | T21: x | U21: x | V21: x | W21: x | X21: x | Y21: JAN 5- indulás
A22: Ércz József | B22: 32 | C22: 4 | D22: =COUNTIF(F22:DW22,"x") -> 5 | E22: =C22-D22 -> -1 | T22: x | U22: x | V22: x | W22: x | X22: x | Y22: JAN 3 belföld, JAN 4 indulás
A23: Falusi Ferenc Sándor | B23: 30 | C23: 6 | D23: =COUNTIF(F23:DW23,"x") -> 5 | E23: =C23-D23 -> 1 | T23: x | U23: x | V23: x | W23: x | X23: x | Y23: JAN 4- indulás
A24: Farkas Attila | B24: 30 | C24: 18 | D24: =COUNTIF(F24:DW24,"x") -> 0 | E24: =C24-D24 -> 18
A25: Farkas Bálint | B25: 8 | C25: 5 | D25: =COUNTIF(F25:DW25,"x") -> 0 | E25: =C25-D25 -> 5
A26: Farkas Rudolf Attila | B26: 30 | C26: 4 | D26: =COUNTIF(F26:DW26,"x") -> 8 | E26: =C26-D26 -> -4 | P26: x | R26: x | S26: x | T26: x | U26: x | V26: x | W26: x | X26: x | Y26: JAN 3- indulás
A27: Fehér Imre | B27: 30 | C27: 12 | D27: =COUNTIF(F27:DW27,"x") -> 6 | E27: =C27-D27 -> 6 | P27: x | T27: x | U27: x | V27: x | W27: x | X27: x | Y27: JAN 10 kezdés
A28: Fehér Róbert | B28: 22 | C28: 4 | D28: =COUNTIF(F28:DW28,"x") -> 6 | E28: =C28-D28 -> -2 | P28: x | T28: x | U28: x | V28: x | W28: x | X28: x | Y28: JAN 10 kezdés
A29: Fenyvesi Zsolt | B29: 30 | C29: 0 | D29: =COUNTIF(F29:DW29,"x") -> 0 | E29: =C29-D29 -> 0 | Y29: 2 ünnep között ki, Jan 1-12-ig szabi, 12-én reggel tud indulni
A30: Fodor Károly | B30: 30 | C30: 17 | D30: =COUNTIF(F30:DW30,"x") -> 5 | E30: =C30-D30 -> 12 | T30: x | U30: x | V30: x | W30: x | X30: x | Y30: JAN 5- indulás, ha nincs munka akkor JAN 10
A31: Fodor Zsolt | B31: 30 | C31: 2 | D31: =COUNTIF(F31:DW31,"x") -> 5 | E31: =C31-D31 -> -3 | T31: x | U31: x | V31: x | W31: x | X31: x | Y31: DEC 21-én lejár a jogsija, indulást egyeztetni
A32: Gárdonyi Tibor Zsolt | B32: 30 | C32: 2 | D32: =COUNTIF(F32:DW32,"x") -> 0 | E32: =C32-D32 -> 2
A33: Gerstmayer Zoltán | B33: 30 | C33: 4 | D33: =COUNTIF(F33:DW33,"x") -> 5 | E33: =C33-D33 -> -1 | T33: x | U33: x | V33: x | W33: x | X33: x | Y33: JAN 3- indulás
A34: Gérus Elemér | B34: 35 | C34: 21 | D34: =COUNTIF(F34:DW34,"x") -> 0 | E34: =C34-D34 -> 21
A35: Giber Zoltán | B35: 34 | C35: 7 | D35: =COUNTIF(F35:DW35,"x") -> 7 | E35: =C35-D35 -> 0 | O35: x | P35: x | T35: x | U35: x | V35: x | W35: x | X35: x | Y35: Ha kell akkor 31-én tud indulni
A36: Glázer János | B36: 31 | C36: 17 | D36: =COUNTIF(F36:DW36,"x") -> 4 | E36: =C36-D36 -> 13 | U36: x | V36: x | W36: x | X36: x | Y36: JAN 2- indulás
A37: Gonda Gergő | B37: 26 | C37: 19 | D37: =COUNTIF(F37:DW37,"x") -> 5 | E37: =C37-D37 -> 14 | T37: x | U37: x | V37: x | W37: x | X37: x
A38: Gonda Róbert | B38: 30 | C38: 22 | D38: =COUNTIF(F38:DW38,"x") -> 9 | E38: =C38-D38 -> 13 | M38: x | N38: x | O38: x | P38: x | T38: x | U38: x | V38: x | W38: x | X38: x | Y38: Amint lehet indulna Januárban
A39: Hallók Gábor | B39: 30 | C39: 18 | D39: =COUNTIF(F39:DW39,"x") -> 5 | E39: =C39-D39 -> 13 | T39: x | U39: x | V39: x | W39: x | X39: x | Y39: JAN 3- indulás
A40: Hamecz Zsolt | B40: 30 | C40: 28 | D40: =COUNTIF(F40:DW40,"x") -> 9 | E40: =C40-D40 -> 19 | M40: x | N40: x | O40: x | P40: x | T40: x | U40: x | V40: x | W40: x | X40: x | Y40: JAN 3 indulás
...

Sheet Szabik 2022
A1: X -et rakj abba a cellába, ahol szabadságot akarsz rögzíteni!! | G1: Munkaszüneti nap | CB1: Áthelyezett pihenőnap | CC1: Munkaszüneti nap | CN1: Áthelyezett munkanap | DI1: Munkaszüneti nap | DL1: Munkaszüneti nap | DY1: Munkaszüneti nap | FI1: Munkaszüneti nap | IF1: Munkaszüneti nap | JX1: DE tilalom 00-22 | KJ1: Áthelyezett munkanap | KR1: Munkaszüneti nap | KZ1: Áthelyezett pihenőnap | LA1: Munkaszüneti nap | NC1: Munkaszüneti nap | ND1: Munkaszüneti nap
B2: ezt ne piszkáld | C2: ezt ne piszkáld | D2: ezt ne piszkáld | E2: ezt se | F2: ezt se | G2: Szombat | H2: Vasárnap | I2: Hétfő | J2: Kedd | K2: Szerda | L2: Csütörtök | M2: Péntek | N2: Szombat | O2: Vasárnap | P2: Hétfő | Q2: Kedd | R2: Szerda | S2: Csütörtök | T2: Péntek | U2: Szombat | V2: Vasárnap | W2: Hétfő | X2: Kedd | Y2: Szerda | Z2: Csütörtök | AA2: Péntek | AB2: Szombat | AC2: Vasárnap | AD2: Hétfő | AE2: Kedd | AF2: Szerda | AG2: Csütörtök | AH2: Péntek | AI2: Szombat | AJ2: Vasárnap | AK2: Hétfő | AL2: Kedd | AM2: Szerda | AN2: Csütörtök | AO2: Péntek | AP2: Szombat | AQ2: Vasárnap | AR2: Hétfő | AS2: Kedd | AT2: Szerda | AU2: Csütörtök | AV2: Péntek | AW2: Szombat | AX2: Vasárnap | AY2: Hétfő | AZ2: Kedd | BA2: Szerda | BB2: Csütörtök | BC2: Péntek | BD2: Szombat | BE2: Vasárnap | BF2: Hétfő | BG2: Kedd | BH2: Szerda | BI2: Csütörtök | BJ2: Péntek | BK2: Szombat | BL2: Vasárnap | BM2: Hétfő | BO2: Kedd | BP2: Szerda | BQ2: Csütörtök | BR2: Péntek | BS2: Szombat | BT2: Vasárnap | BU2: Hétfő | BV2: Kedd | BW2: Szerda | BX2: Csütörtök | BY2: Péntek | BZ2: Szombat | CA2: Vasárnap | CB2: Hétfő | CC2: Kedd | CD2: Szerda | CE2: Csütörtök | CF2: Péntek | CG2: Szombat | CH2: Vasárnap | CI2: Hétfő | CJ2: Kedd | CK2: Szerda | CL2: Csütörtök | CM2: Péntek | CN2: Szombat | CO2: Vasárnap | CP2: Hétfő | CQ2: Kedd | CR2: Szerda | CS2: Csütörtök | CU2: Péntek | CV2: Szombat | CW2: Vasárnap | CX2: Hétfő | CY2: Kedd | CZ2: Szerda | DA2: Csütörtök | DB2: Péntek | DC2: Szombat | DD2: Vasárnap | DE2: Hétfő | DF2: Kedd | DG2: Szerda | DH2: Csütörtök | DI2: Péntek | DJ2: Szombat | DK2: Vasárnap | DL2: Hétfő | DM2: Kedd | DN2: Szerda | DO2: Csütörtök | DP2: Péntek | DQ2: Szombat | DR2: Vasárnap | DS2: Hétfő | DT2: Kedd | DU2: Szerda | DV2: Csütörtök | DW2: Péntek | DX2: Szombat | DY2: Vasárnap | DZ2: Hétfő | EA2: Kedd | EB2: Szerda | EC2: Csütörtök | ED2: Péntek | EE2: Szombat | EF2: Vasárnap | EG2: Hétfő | EH2: Kedd | EI2: Szerda | EJ2: Csütörtök | EK2: Péntek | EL2: Szombat | EM2: Vasárnap | EN2: Hétfő | EO2: Kedd | EP2: Szerda | EQ2: Csütörtök | ER2: Péntek | ES2: Szombat | ET2: Vasárnap | EU2: Hétfő | EV2: Kedd | EW2: Szerda | EX2: Csütörtök | EY2: Péntek | EZ2: Szombat | FA2: Vasárnap | FB2: Hétfő | FC2: Kedd | FD2: Szerda | FE2: Csütörtök | FF2: Péntek | FG2: Szombat | FH2: Vasárnap | FI2: Hétfő | FJ2: Kedd | FK2: Szerda | FL2: Csütörtök | FM2: Péntek | FN2: Szombat | FO2: Vasárnap | FP2: Hétfő | FQ2: Kedd | FR2: Szerda | FS2: Csütörtök | FT2: Péntek | FU2: Szombat | FV2: Vasárnap | FW2: Hétfő | FX2: Kedd | FY2: Szerda | FZ2: Csütörtök | GA2: Péntek | GB2: Szombat | GC2: Vasárnap | GD2: Hétfő | GE2: Kedd | GF2: Szerda | GG2: Csütörtök | GH2: Péntek | GI2: Szombat | GJ2: Vasárnap | GK2: Hétfő | GL2: Kedd | GM2: Szerda | GN2: Csütörtök | GO2: Péntek | GP2: Szombat | GQ2: Vasárnap | GR2: Hétfő | GS2: Kedd | GT2: Szerda | GU2: Csütörtök | GV2: Péntek | GW2: Szombat | GX2: Vasárnap | GY2: Hétfő | GZ2: Kedd | HA2: Szerda | HB2: Csütörtök | HC2: Péntek | HD2: Szombat | HE2: Vasárnap | HF2: Hétfő | HG2: Kedd | HH2: Szerda | HI2: Csütörtök | HJ2: Péntek | HK2: Szombat | HL2: Vasárnap | HM2: Hétfő | HN2: Kedd | HO2: Szerda | HP2: Csütörtök | HQ2: Péntek | HR2: Szombat | HS2: Vasárnap | HT2: Hétfő | HU2: Kedd | HV2: Szerda | HW2: Csütörtök | HX2: Péntek | HY2: Szombat | HZ2: Vasárnap | IA2: Hétfő | IB2: Kedd | IC2: Szerda | ID2: Csütörtök | IE2: Péntek | IF2: Szombat | IG2: Vasárnap | IH2: Hétfő | II2: Kedd | IJ2: Szerda | IK2: Csütörtök | IL2: Péntek | IM2: Szombat | IN2: Vasárnap | IO2: Hétfő | IP2: Kedd | IQ2: Szerda | IR2: Csütörtök | IS2: Péntek | IT2: Szombat | IU2: Vasárnap | IV2: Hétfő | IW2: Kedd | IX2: Szerda | IY2: Csütörtök | IZ2: Péntek | JA2: Szombat | JB2: Vasárnap | JC2: Hétfő | JD2: Kedd | JE2: Szerda | JF2: Csütörtök | JG2: Péntek | JH2: Szombat | JI2: Vasárnap | JJ2: Hétfő | JK2: Kedd | JL2: Szerda | JM2: Csütörtök | JN2: Péntek | JO2: Szombat | JP2: Vasárnap | JQ2: Hétfő | JR2: Kedd | JS2: Szerda | JT2: Csütörtök | JU2: Péntek | JV2: Szombat | JW2: Vasárnap | JX2: Hétfő | JY2: Kedd | JZ2: Szerda | KA2: Csütörtök | KB2: Péntek | KC2: Szombat | KD2: Vasárnap | KE2: Hétfő | KF2: Kedd | KG2: Szerda | KH2: Csütörtök | KI2: Péntek | KJ2: Szombat | KK2: Vasárnap | KL2: Hétfő | KM2: Kedd | KN2: Szerda | KO2: Csütörtök | KP2: Péntek | KQ2: Szombat | KR2: Vasárnap | KS2: Hétfő | KT2: Kedd | KU2: Szerda | KV2: Csütörtök | KW2: Péntek | KX2: Szombat | KY2: Vasárnap | KZ2: Hétfő | LA2: Kedd | LB2: Szerda | LC2: Csütörtök | LD2: Péntek | LE2: Szombat | LF2: Vasárnap | LG2: Hétfő | LH2: Kedd | LI2: Szerda | LJ2: Csütörtök | LK2: Péntek | LL2: Szombat | LM2: Vasárnap | LN2: Hétfő | LO2: Kedd | LP2: Szerda | LQ2: Csütörtök | LR2: Péntek | LS2: Szombat | LT2: Vasárnap | LU2: Hétfő | LV2: Kedd | LW2: Szerda | LX2: Csütörtök | LY2: Péntek | LZ2: Szombat | MA2: Vasárnap | MB2: Hétfő | MC2: Kedd | MD2: Szerda | ME2: Csütörtök | MF2: Péntek | MG2: Szombat | MH2: Vasárnap | MI2: Hétfő | MJ2: Kedd | MK2: Szerda | ML2: Csütörtök | MM2: Péntek | MN2: Szombat | MO2: Vasárnap | MP2: Hétfő | MQ2: Kedd | MR2: Szerda | MS2: Csütörtök | MT2: Péntek | MU2: Szombat | MV2: Vasárnap | MW2: Hétfő | MX2: Kedd | MY2: Szerda | MZ2: Csütörtök | NA2: Péntek | NB2: Szombat | NC2: Vasárnap | ND2: Hétfő | NE2: Kedd | NF2: Szerda | NG2: Csütörtök | NH2: Péntek | NI2: Szombat | NJ2: Vasárnap | NK2: Hétfő | NL2: Kedd | NM2: Szerda | NN2: Csütörtök | NO2: Péntek | NP2: Szombat | NQ2: Vasárnap | NR2: Hétfő | NS2: Kedd | NT2: Szerda | NU2: Csütörtök | NV2: Péntek | NW2: Szombat | NX2: Vasárnap | NY2: Hétfő | NZ2: Kedd | OA2: Szerda | OB2: Csütörtök | OC2: Péntek | OD2: Szombat | OE2: Vasárnap | OF2: Hétfő | OG2: Kedd | OH2: Szerda | OI2: Csütörtök | OJ2: Péntek | OK2: Szombat | OL2: Vasárnap | OM2: Hétfő | ON2: Kedd | OO2: Szerda | OP2: Csütörtök | OQ2: Péntek | OR2: Szombat | OS2: Vasárnap | OT2: Hétfő | OU2: Kedd | OV2: Szerda | OW2: Csütörtök | OX2: Péntek | OY2: Szombat | OZ2: Vasárnap | PA2: Hétfő | PB2: Kedd | PC2: Szerda | PD2: Csütörtök | PE2: Péntek | PF2: Szombat | PG2: Vasárnap | PH2: Hétfő | PI2: Kedd | PJ2: Szerda | PK2: Csütörtök | PL2: Péntek | PM2: Szombat | PN2: Vasárnap | PO2: Hétfő | PP2: Kedd
A3: Név | B3: Összes 2022-ben kivehető Szabadság | C3: Április 30ig kivett | D3: Szeptember 30-ig kivett | E3: Tervezet | F3: Még felhasználható szabadság 2022-ben | G3: január 1. | H3: január 2. | I3: január 3. | J3: január 4. | K3: január 5. | L3: január 6. | M3: január 7. | N3: január 8. | O3: január 9. | P3: január 10. | Q3: január 11. | R3: január 12. | S3: január 13. | T3: január 14. | U3: január 15. | V3: január 16. | W3: január 17. | X3: január 18. | Y3: január 19. | Z3: január 20. | AA3: január 21. | AB3: január 22. | AC3: január 23. | AD3: január 24. | AE3: január 25. | AF3: január 26. | AG3: január 27. | AH3: január 28. | AI3: január 29. | AJ3: január 30. | AK3: január 31. | AL3: február 1. | AM3: február 2. | AN3: február 3. | AO3: február 4. | AP3: február 5. | AQ3: február 6. | AR3: február 7. | AS3: február 8. | AT3: február 9. | AU3: február 10. | AV3: február 11. | AW3: február 12. | AX3: február 13. | AY3: február 14. | AZ3: február 15. | BA3: február 16. | BB3: február 17. | BC3: február 18. | BD3: február 19. | BE3: február 20. | BF3: február 21. | BG3: február 22. | BH3: február 23. | BI3: február 24. | BJ3: február 25. | BK3: február 26. | BL3: február 27. | BM3: február 28. | BN3: Jan&Feb összesítő | BO3: március 1. | BP3: március 2. | BQ3: március 3. | BR3: március 4. | BS3: március 5. | BT3: március 6. | BU3: március 7. | BV3: március 8. | BW3: március 9. | BX3: március 10. | BY3: március 11. | BZ3: március 12. | CA3: március 13. | CB3: március 14. | CC3: március 15. | CD3: március 16. | CE3: március 17. | CF3: március 18. | CG3: március 19. | CH3: március 20. | CI3: március 21. | CJ3: március 22. | CK3: március 23. | CL3: március 24. | CM3: március 25. | CN3: március 26. | CO3: március 27. | CP3: március 28. | CQ3: március 29. | CR3: március 30. | CS3: március 31. | CT3: Márciusi DB | CU3: április 1. | CV3: április 2. | CW3: április 3. | CX3: április 4. | CY3: április 5. | CZ3: április 6. | DA3: április 7. | DB3: április 8. | DC3: április 9. | DD3: április 10. | DE3: április 11. | DF3: április 12. | DG3: április 13. | DH3: április 14. | DI3: április 15. | DJ3: április 16. | DK3: április 17. | DL3: április 18. | DM3: április 19. | DN3: április 20. | DO3: április 21. | DP3: április 22. | DQ3: április 23. | DR3: április 24. | DS3: április 25. | DT3: április 26. | DU3: április 27. | DV3: április 28. | DW3: április 29. | DX3: április 30. | DY3: május 1. | DZ3: május 2. | EA3: május 3. | EB3: május 4. | EC3: május 5. | ED3: május 6. | EE3: május 7. | EF3: május 8. | EG3: május 9. | EH3: május 10. | EI3: május 11. | EJ3: május 12. | EK3: május 13. | EL3: május 14. | EM3: május 15. | EN3: május 16. | EO3: május 17. | EP3: május 18. | EQ3: május 19. | ER3: május 20. | ES3: május 21. | ET3: május 22. | EU3: május 23. | EV3: május 24. | EW3: május 25. | EX3: május 26. | EY3: május 27. | EZ3: május 28. | FA3: május 29. | FB3: május 30. | FC3: május 31. | FD3: június 1. | FE3: június 2. | FF3: június 3. | FG3: június 4. | FH3: június 5. | FI3: június 6. | FJ3: június 7. | FK3: június 8. | FL3: június 9. | FM3: június 10. | FN3: június 11. | FO3: június 12. | FP3: június 13. | FQ3: június 14. | FR3: június 15. | FS3: június 16. | FT3: június 17. | FU3: június 18. | FV3: június 19. | FW3: június 20. | FX3: június 21. | FY3: június 22. | FZ3: június 23. | GA3: június 24. | GB3: június 25. | GC3: június 26. | GD3: június 27. | GE3: június 28. | GF3: június 29. | GG3: június 30. | GH3: július 1. | GI3: július 2. | GJ3: július 3. | GK3: július 4. | GL3: július 5. | GM3: július 6. | GN3: július 7. | GO3: július 8. | GP3: július 9. | GQ3: július 10. | GR3: július 11. | GS3: július 12. | GT3: július 13. | GU3: július 14. | GV3: július 15. | GW3: július 16. | GX3: július 17. | GY3: július 18. | GZ3: július 19. | HA3: július 20. | HB3: július 21. | HC3: július 22. | HD3: július 23. | HE3: július 24. | HF3: július 25. | HG3: július 26. | HH3: július 27. | HI3: július 28. | HJ3: július 29. | HK3: július 30. | HL3: július 31. | HM3: augusztus 1. | HN3: augusztus 2. | HO3: augusztus 3. | HP3: augusztus 4. | HQ3: augusztus 5. | HR3: augusztus 6. | HS3: augusztus 7. | HT3: augusztus 8. | HU3: augusztus 9. | HV3: augusztus 10. | HW3: augusztus 11. | HX3: augusztus 12. | HY3: augusztus 13. | HZ3: augusztus 14. | IA3: augusztus 15. | IB3: augusztus 16. | IC3: augusztus 17. | ID3: augusztus 18. | IE3: augusztus 19. | IF3: augusztus 20. | IG3: augusztus 21. | IH3: augusztus 22. | II3: augusztus 23. | IJ3: augusztus 24. | IK3: augusztus 25. | IL3: augusztus 26. | IM3: augusztus 27. | IN3: augusztus 28. | IO3: augusztus 29. | IP3: augusztus 30. | IQ3: augusztus 31. | IR3: szeptember 1. | IS3: szeptember 2. | IT3: szeptember 3. | IU3: szeptember 4. | IV3: szeptember 5. | IW3: szeptember 6. | IX3: szeptember 7. | IY3: szeptember 8. | IZ3: szeptember 9. | JA3: szeptember 10. | JB3: szeptember 11. | JC3: szeptember 12. | JD3: szeptember 13. | JE3: szeptember 14. | JF3: szeptember 15. | JG3: szeptember 16. | JH3: szeptember 17. | JI3: szeptember 18. | JJ3: szeptember 19. | JK3: szeptember 20. | JL3: szeptember 21. | JM3: szeptember 22. | JN3: szeptember 23. | JO3: szeptember 24. | JP3: szeptember 25. | JQ3: szeptember 26. | JR3: szeptember 27. | JS3: szeptember 28. | JT3: szeptember 29. | JU3: szeptember 30. | JV3: október 1. | JW3: október 2. | JX3: október 3. | JY3: október 4. | JZ3: október 5. | KA3: október 6. | KB3: október 7. | KC3: október 8. | KD3: október 9. | KE3: október 10. | KF3: október 11. | KG3: október 12. | KH3: október 13. | KI3: október 14. | KJ3: október 15. | KK3: október 16. | KL3: október 17. | KM3: október 18. | KN3: október 19. | KO3: október 20. | KP3: október 21. | KQ3: október 22. | KR3: október 23. | KS3: október 24. | KT3: október 25. | KU3: október 26. | KV3: október 27. | KW3: október 28. | KX3: október 29. | KY3: október 30. | KZ3: október 31. | LA3: november 1. | LB3: november 2. | LC3: november 3. | LD3: november 4. | LE3: november 5. | LF3: november 6. | LG3: november 7. | LH3: november 8. | LI3: november 9. | LJ3: november 10. | LK3: november 11. | LL3: november 12. | LM3: november 13. | LN3: november 14. | LO3: november 15. | LP3: november 16. | LQ3: november 17. | LR3: november 18. | LS3: november 19. | LT3: november 20. | LU3: november 21. | LV3: november 22. | LW3: november 23. | LX3: november 24. | LY3: november 25. | LZ3: november 26. | MA3: november 27. | MB3: november 28. | MC3: november 29. | MD3: november 30. | ME3: december 1. | MF3: december 2. | MG3: december 3. | MH3: december 4. | MI3: december 5. | MJ3: december 6. | MK3: december 7. | ML3: december 8. | MM3: december 9. | MN3: december 10. | MO3: december 11. | MP3: december 12. | MQ3: december 13. | MR3: december 14. | MS3: december 15. | MT3: december 16. | MU3: december 17. | MV3: december 18. | MW3: december 19. | MX3: december 20. | MY3: december 21. | MZ3: december 22. | NA3: december 23. | NB3: december 24. | NC3: december 25. | ND3: december 26. | NE3: december 27. | NF3: december 28. | NG3: december 29. | NH3: december 30. | NI3: december 31. | NJ3: Január 1. | NK3: Január 2. | NL3: Január 3. | NM3: Január 4 | NN3: Január 5. | NO3: Január 6. | NP3: Január 7. | NQ3: Január 8. | NR3: Január 9. | NS3: január 10. | NT3: január 11. | NU3: január 12. | NV3: január 13. | NW3: január 14. | NX3: január 15. | NY3: január 16. | NZ3: január 17. | OA3: január 18. | OB3: január 19. | OC3: január 20. | OD3: január 21. | OE3: január 22. | OF3: január 23. | OG3: január 24. | OH3: január 25. | OI3: január 26. | OJ3: január 27. | OK3: január 28. | OL3: január 29. | OM3: január 30. | ON3: január 31. | OO3: február 1. | OP3: február 2. | OQ3: február 3. | OR3: február 4. | OS3: február 5. | OT3: február 6. | OU3: február 7. | OV3: február 8. | OW3: február 9. | OX3: február 10. | OY3: február 11. | OZ3: február 12. | PA3: február 13. | PB3: február 14. | PC3: február 15. | PD3: február 16. | PE3: február 17. | PF3: február 18. | PG3: február 19. | PH3: február 20. | PI3: február 21. | PJ3: február 22. | PK3: február 23. | PL3: február 24. | PM3: február 25. | PN3: február 26. | PO3: február 27. | PP3: február 28. | PQ3: március 1. | PR3: március 2. | PS3: március 3. | PT3: március 4. | PU3: március 5. | PV3: március 6. | PW3: március 7. | PX3: március 8. | PY3: március 9. | PZ3: március 10. | QA3: március 11. | QB3: március 12. | QC3: március 13. | QD3: március 14. | QE3: március 15. | QF3: március 16. | QG3: március 17. | QH3: március 18. | QI3: március 19. | QJ3: március 20. | QK3: március 21. | QL3: március 22. | QM3: március 23. | QN3: március 24. | QO3: március 25. | QP3: március 26. | QQ3: március 27. | QR3: március 28. | QS3: március 29. | QT3: március 30. | QU3: március 31. | QV3: Márciusi DB | QW3: április 1. | QX3: április 2. | QY3: április 3. | QZ3: április 4. | RA3: április 5. | RB3: április 6. | RC3: április 7. | RD3: április 8. | RE3: április 9. | RF3: április 10. | RG3: április 11. | RH3: április 12. | RI3: április 13. | RJ3: április 14. | RK3: április 15. | RL3: április 16. | RM3: április 17. | RN3: április 18. | RO3: április 19. | RP3: április 20. | RQ3: április 21. | RR3: április 22. | RS3: április 23. | RT3: április 24. | RU3: április 25. | RV3: április 26. | RW3: április 27. | RX3: április 28. | RY3: április 29. | RZ3: április 30. | SA3: május 1. | SB3: május 2. | SC3: május 3. | SD3: május 4. | SE3: május 5. | SF3: május 6. | SG3: május 7. | SH3: május 8. | SI3: május 9. | SJ3: május 10. | SK3: május 11. | SL3: május 12. | SM3: május 13. | SN3: május 14. | SO3: május 15. | SP3: május 16. | SQ3: május 17. | SR3: május 18. | SS3: május 19. | ST3: május 20. | SU3: május 21. | SV3: május 22. | SW3: május 23. | SX3: május 24. | SY3: május 25. | SZ3: május 26. | TA3: május 27. | TB3: május 28. | TC3: május 29. | TD3: május 30. | TE3: május 31. | TF3: június 1. | TG3: június 2. | TH3: június 3. | TI3: június 4. | TJ3: június 5. | TK3: június 6. | TL3: június 7. | TM3: június 8. | TN3: június 9. | TO3: június 10. | TP3: június 11. | TQ3: június 12. | TR3: június 13. | TS3: június 14. | TT3: június 15. | TU3: június 16. | TV3: június 17. | TW3: június 18. | TX3: június 19. | TY3: június 20. | TZ3: június 21. | UA3: június 22. | UB3: június 23. | UC3: június 24. | UD3: június 25. | UE3: június 26. | UF3: június 27. | UG3: június 28. | UH3: június 29. | UI3: június 30. | UJ3: július 1. | UK3: július 2. | UL3: július 3. | UM3: július 4. | UN3: július 5. | UO3: július 6. | UP3: július 7. | UQ3: július 8. | UR3: július 9. | US3: július 10. | UT3: július 11. | UU3: július 12. | UV3: július 13. | UW3: július 14. | UX3: július 15. | UY3: július 16. | UZ3: július 17. | VA3: július 18. | VB3: július 19. | VC3: július 20. | VD3: július 21. | VE3: július 22. | VF3: július 23. | VG3: július 24. | VH3: július 25. | VI3: július 26. | VJ3: július 27. | VK3: július 28. | VL3: július 29. | VM3: július 30. | VN3: július 31. | VO3: augusztus 1. | VP3: augusztus 2. | VQ3: augusztus 3. | VR3: augusztus 4. | VS3: augusztus 5. | VT3: augusztus 6. | VU3: augusztus 7. | VV3: augusztus 8. | VW3: augusztus 9. | VX3: augusztus 10. | VY3: augusztus 11. | VZ3: augusztus 12. | WA3: augusztus 13. | WB3: augusztus 14. | WC3: augusztus 15. | WD3: augusztus 16. | WE3: augusztus 17. | WF3: augusztus 18. | WG3: augusztus 19. | WH3: augusztus 20. | WI3: augusztus 21. | WJ3: augusztus 22. | WK3: augusztus 23. | WL3: augusztus 24. | WM3: augusztus 25. | WN3: augusztus 26. | WO3: augusztus 27. | WP3: augusztus 28. | WQ3: augusztus 29. | WR3: augusztus 30. | WS3: augusztus 31. | WT3: szeptember 1. | WU3: szeptember 2. | WV3: szeptember 3. | WW3: szeptember 4. | WX3: szeptember 5. | WY3: szeptember 6. | WZ3: szeptember 7. | XA3: szeptember 8. | XB3: szeptember 9. | XC3: szeptember 10. | XD3: szeptember 11. | XE3: szeptember 12. | XF3: szeptember 13. | XG3: szeptember 14. | XH3: szeptember 15. | XI3: szeptember 16. | XJ3: szeptember 17. | XK3: szeptember 18. | XL3: szeptember 19. | XM3: szeptember 20. | XN3: szeptember 21. | XO3: szeptember 22. | XP3: szeptember 23. | XQ3: szeptember 24. | XR3: szeptember 25. | XS3: szeptember 26. | XT3: szeptember 27. | XU3: szeptember 28. | XV3: szeptember 29. | XW3: szeptember 30. | XX3: október 1. | XY3: október 2. | XZ3: október 3. | YA3: október 4. | YB3: október 5. | YC3: október 6. | YD3: október 7. | YE3: október 8. | YF3: október 9. | YG3: október 10. | YH3: október 11. | YI3: október 12. | YJ3: október 13. | YK3: október 14. | YL3: október 15. | YM3: október 16. | YN3: október 17. | YO3: október 18. | YP3: október 19. | YQ3: október 20. | YR3: október 21. | YS3: október 22. | YT3: október 23. | YU3: október 24. | YV3: október 25. | YW3: október 26. | YX3: október 27. | YY3: október 28. | YZ3: október 29. | ZA3: október 30. | ZB3: október 31. | ZC3: november 1. | ZD3: november 2. | ZE3: november 3. | ZF3: november 4. | ZG3: november 5. | ZH3: november 6. | ZI3: november 7. | ZJ3: november 8. | ZK3: november 9. | ZL3: november 10. | ZM3: november 11. | ZN3: november 12. | ZO3: november 13. | ZP3: november 14. | ZQ3: november 15. | ZR3: november 16. | ZS3: november 17. | ZT3: november 18. | ZU3: november 19. | ZV3: november 20. | ZW3: november 21. | ZX3: november 22. | ZY3: november 23. | ZZ3: november 24. | AAA3: november 25. | AAB3: november 26. | AAC3: november 27. | AAD3: november 28. | AAE3: november 29. | AAF3: november 30. | AAG3: december 1. | AAH3: december 2. | AAI3: december 3. | AAJ3: december 4. | AAK3: december 5. | AAL3: december 6. | AAM3: december 7. | AAN3: december 8. | AAO3: december 9. | AAP3: december 10. | AAQ3: december 11. | AAR3: december 12. | AAS3: december 13. | AAT3: december 14. | AAU3: december 15. | AAV3: december 16. | AAW3: december 17. | AAX3: december 18. | AAY3: december 19. | AAZ3: december 20. | ABA3: december 21. | ABB3: december 22. | ABC3: december 23. | ABD3: december 24. | ABE3: december 25. | ABF3: december 26. | ABG3: december 27. | ABH3: december 28. | ABI3: december 29. | ABJ3: december 30. | ABK3: december 31.
G4: =COUNTA(G5:G126) -> 0 | H4: =COUNTA(H5:H126) -> 0 | I4: =COUNTA(I5:I126) -> 46 | J4: =COUNTA(J5:J126) -> 28 | K4: =COUNTA(K5:K126) -> 19 | L4: =COUNTA(L5:L126) -> 28 | M4: =COUNTA(M5:M126) -> 21 | N4: =COUNTA(N5:N126) -> 0 | ... BM4: =COUNTA(BM5:BM126) -> 19 | BO4: =COUNTA(BO5:BO126) -> 15 | BP4: =COUNTA(BP5:BP126) -> 5 | BQ4: =COUNTA(BQ5:BQ126) -> 11 | BR4: =COUNTA(BR5:BR126) -> 21 | BS4: =COUNTA(BS5:BS126) -> 14 | BT4: =COUNTA(BT5:BT126) -> 14 | BU4: =COUNTA(BU5:BU126) -> 18 | BV4: =COUNTA(BV5:BV126) -> 14 | ... CS4: =COUNTA(CS5:CS126) -> 8 | CU4: =COUNTA(CU5:CU126) -> 34 | CV4: =COUNTA(CV5:CV126) -> 5 | CW4: =COUNTA(CW5:CW126) -> 2 | CX4: =COUNTA(CX5:CX126) -> 17 | CY4: =COUNTA(CY5:CY126) -> 13 | CZ4: =COUNTA(CZ5:CZ126) -> 9 | DA4: =COUNTA(DA5:DA126) -> 15 | DB4: =COUNTA(DB5:DB126) -> 20 | ... PP4: =COUNTA(PP5:PP126) -> 0
A5: Adamek István | B5: 30 | C5: =COUNTIF(F5:DX5,"x") -> 0 | D5: 16 | E5: =COUNTIF(JU5:NI5,"x") -> 9 | F5: =+B5-D5-E5 -> 5 | AR5: B | AS5: B | AT5: B | AU5: B | AV5: B | AY5: B | AZ5: B | BA5: B | BB5: B | BC5: B | BN5: =COUNTIFS(G5:BM5,"x") -> 0 | BS5: P | BT5: P | CB5: P | CT5: =COUNTIF(BO5:CS5,"X") -> 0 | ER5: X | FE5: X | FF5: X | FG5: P | FH5: P | FI5: P | HK5: P | HL5: P | HM5: X | HN5: X | HO5: X | HP5: X | HQ5: X | HR5: P | HS5: P | HT5: X | HU5: X | HV5: X | HW5: X | HX5: X | HY5: P | HZ5: P | IX5: x | JI5: B | JJ5: B | JK5: B | JL5: B | JM5: B | JN5: B | JO5: B | JP5: B | JQ5: B | JR5: B | JS5: B | JT5: B | JU5: B | NA5: x | NB5: x | NC5: x | ND5: x | NE5: x | NF5: x | NG5: x | NH5: x | NI5: x | NJ5: vasárnapi esti induló
A6: Árvai József | B6: 31 | C6: =COUNTIF(F6:DX6,"x") -> 9 | D6: 17 | E6: =COUNTIF(JU6:NI6,"x") -> 0 | F6: =+B6-D6-E6 -> 14 | M6: x | P6: x | S6: x | T6: x | AD6: x | AR6: X | BF6: X | BN6: =COUNTIFS(G6:BM6,"x") -> 7 | BU6: X | CB6: P | CI6: X | CT6: =COUNTIF(BO6:CS6,"X") -> 2 | CX6: P | DZ6: p | EN6: P | EY6: X | EZ6: P | FB6: X | FN6: P | FT6: X | GD6: X | GR6: X | HT6: P | IE6: X | IF6: P | IG6: P | IH6: X | JG6: X | JH6: P | JI6: P | NE6: DSV kört csinálja két ünnep között | NM6: indul
A7: Bagi Lajos | B7: 35 | C7: =COUNTIF(F7:DX7,"x") -> 5 | D7: 15 | E7: =COUNTIF(JU7:NI7,"x") -> 22 | F7: =+B7-D7-E7 -> -2 | AN7: x | AO7: x | AP7: o | AQ7: o | BN7: =COUNTIFS(G7:BM7,"x") -> 2 | CI7: B | CJ7: B | CK7: B | CL7: B | CM7: B | CN7: X | CT7: =COUNTIF(BO7:CS7,"X") -> 1 | CU7: X | DH7: X | DI7: P | DJ7: P | DK7: P | DL7: P | EX7: X | EY7: X | EZ7: P | FW7: X | GK7: X | GT7: X | GU7: X | GV7: X | GW7: P | GX7: P | GY7: X | HM7: X | IA7: P | IO7: P | JC7: x | KR7: x | KS7: x | KT7: x | KU7: x | KV7: x | KW7: x | KX7: x | KY7: x | KZ7: x | MW7: x | MX7: x | MY7: x | MZ7: x | NA7: x | NB7: x | NC7: x | ND7: x | NE7: x | NF7: x | NG7: x | NH7: x | NI7: x | NJ7: x | NK7: indulás
A8: Bagi Márió Lajos | B8: 23 | C8: =COUNTIF(F8:DX8,"x") -> 4 | D8: 14 | E8: =COUNTIF(JU8:NI8,"x") -> 22 | F8: =+B8-D8-E8 -> -13 | AN8: x | AO8: x | AP8: o | AQ8: o | BN8: =COUNTIFS(G8:BM8,"x") -> 2 | CT8: =COUNTIF(BO8:CS8,"X") -> 0 | CU8: X | DH8: X | DI8: P | DJ8: P | DK8: P | DL8: P | EX8: X | EY8: X | EZ8: P | FW8: X | GK8: X | GT8: X | GU8: X | GV8: X | GW8: P | GX8: P | GY8: X | HM8: X | IA8: P | IO8: P | JC8: x | KR8: x | KS8: x | KT8: x | KU8: x | KV8: x | KW8: x | KX8: x | KY8: x | KZ8: x | MW8: x | MX8: x | MY8: x | MZ8: x | NA8: x | NB8: x | NC8: x | ND8: x | NE8: x | NF8: x | NG8: x | NH8: x | NI8: x | NJ8: x | NK8: indulás
A9: Bak László | B9: 33 | C9: =COUNTIF(F9:DX9,"x") -> 4 | D9: 17 | E9: =COUNTIF(JU9:NI9,"x") -> 13 | F9: =+B9-D9-E9 -> 3 | Z9: x | AA9: X | BN9: =COUNTIFS(G9:BM9,"x") -> 2 | CB9: P | CT9: =COUNTIF(BO9:CS9,"X") -> 0 | DJ9: P | DK9: P | DL9: P | DM9: X | DW9: X | DX9: P | DY9: P | EX9: x | EY9: x | EZ9: GKI | FB9: x | FW9: x | FX9: x | FY9: x | FZ9: x | GA9: x | GB9: P | GC9: P | HM9: x | HN9: x | HO9: x | HP9: x | HQ9: x | KE9: B | KF9: B | KG9: B | KH9: B | MW9: x | MX9: x | MY9: x | MZ9: x | NA9: x | NB9: x | NC9: x | ND9: x | NE9: x | NF9: x | NG9: x | NH9: x | NI9: x | NJ9: x | NK9: x | NL9: indulás
A10: Balázs István I. | B10: 46 | C10: =COUNTIF(F10:DX10,"x") -> 4 | D10: 15 | E10: =COUNTIF(JU10:NI10,"x") -> 9 | F10: =+B10-D10-E10 -> 22 | W10: x | BN10: =COUNTIFS(G10:BM10,"x") -> 1 | CI10: X | CN10: X | CT10: =COUNTIF(BO10:CS10,"X") -> 2 | DE10: X | EJ10: X | EK10: x | EL10: ADR | EM10: ADR | HK10: a | HL10: P | HM10: X | HN10: X | HO10: X | HP10: X | HQ10: X | HR10: P | HS10: P | HT10: X | IC10: x | ID10: x | IE10: x | IF10: o | IG10: o | IR10: P | NA10: x | NB10: x | NC10: x | ND10: x | NE10: x | NF10: x | NG10: x | NH10: x | NI10: x | NJ10: x | NK10: indulás
A11: Balázs István II. | MZ11: x | NA11: x | NB11: x | NC11: x | ND11: x | NE11: indulás
A12: Balázs Tibor | B12: 40 | C12: =COUNTIF(F12:DX12,"x") -> 15 | D12: 33 | E12: =COUNTIF(JU12:NI12,"x") -> 3 | F12: =+B12-D12-E12 -> 4 | AA12: x | AN12: x | AO12: x | BC12: x | BN12: =COUNTIFS(G12:BM12,"x") -> 4 | BR12: X | CB12: P | CC12: P | CD12: X | CE12: X | CF12: X | CI12: X | CJ12: X | CM12: X | CT12: =COUNTIF(BO12:CS12,"X") -> 7 | DI12: P | DJ12: P | DK12: P | DL12: P | DM12: x | DN12: x | DO12: x | DP12: x | DQ12: P | DR12: P | EO12: X | EP12: X | EQ12: x | ER12: x | ES12: o | ET12: o | FF12: x | FG12: P | FH12: P | FI12: P | FU12: P | FV12: P | FW12: X | GA12: X | GB12: P | GC12: P | GO12: X | GP12: P | GQ12: P | GY12: X | HF12: x | HG12: x | HH12: x | HI12: x | HJ12: x | HK12: o | HL12: o | HM12: x | HN12: x | HO12: x | HP12: x | HQ12: x | HR12: o | HS12: o | KO12: x | KP12: x | KQ12: o | KR12: o | NB12: P | NC12: P | ND12: P | NF12: egy kanyarra kimegy | NI12: x | NJ12: x | NK12: indulás
A13: Bálint László | B13: 24 | C13: =COUNTIF(F13:DX13,"x") -> 18 | D13: 24 | E13: =COUNTIF(JU13:NI13,"x") -> 15 | F13: =+B13-D13-E13 -> -15 | I13: X | J13: X | P13: x | T13: x | AN13: x | AO13: x | AR13: x | AS13: x | AT13: x | AU13: x | AV13: x | AY13: x | BF13: x | BN13: =COUNTIFS(G13:BM13,"x") -> 13 | BQ13: B | BR13: B | BS13: B | BT13: B | BU13: B | CA13: P | CB13: P | CC13: P | CD13: X | CE13: X | CF13: X | CT13: =COUNTIF(BO13:CS13,"X") -> 3 | DI13: P | DJ13: P | DK13: P | DL13: P | DM13: x | DN13: x | DZ13: X | EX13: X | EY13: X | EZ13: P | FB13: X | FF13: X | FG13: P | FH13: P | FI13: P | FJ13: X | FK13: X | FL13: X | FM13: X | FN13: P | FO13: P | GD13: x | GE13: x | GF13: x | GG13: x | GH13: x | GI13: P | GJ13: P | HC13: X | HD13: GKI | HE13: GKI | HF13: GKI | HM13: x | HN13: GKI | HQ13: X | IA13: X | IM13: o | IN13: o | IO13: x | IP13: x | IQ13: x | IR13: x | IS13: x | JJ13: x | JY13: B | JZ13: B | KA13: B | KB13: B | KX13: x | KY13: x | KZ13: x | LA13: x | MX13: kiszáll | MY13: x | MZ13: x | NA13: x | NB13: x | NC13: x | ND13: x | NE13: x | NF13: x | NG13: x | NH13: x | NI13: x | NJ13: x | NK13: x | NL13: indulás
A14: Csák László | B14: 36 | C14: =COUNTIF(F14:DX14,"x") -> 7 | D14: 18 | E14: =COUNTIF(JU14:NI14,"x") -> 9 | F14: =+B14-D14-E14 -> 9 | AR14: x | BN14: =COUNTIFS(G14:BM14,"x") -> 1 | CD14: X | CE14: X | CT14: =COUNTIF(BO14:CS14,"X") -> 2 | CU14: X | DM14: X | DV14: X | DW14: X | DX14: P | DY14: P | EN14: X | GD14: X | HF14: X | HM14: x | IY14: X | IZ14: X | JA14: P | JB14: P | JC14: X | JD14: X | JE14: X | JF14: X | JG14: X | NA14: x | NB14: x | NC14: x | ND14: x | NE14: x | NF14: x | NG14: x | NH14: x | NI14: x | NJ14: x | NK14: x | NL14: indulás
A15: Csicsai Gábor | B15: 32 | C15: =COUNTIF(F15:DX15,"x") -> 2 | D15: 14 | E15: =COUNTIF(JU15:NI15,"x") -> 20 | F15: =+B15-D15-E15 -> -2 | BC15: x | BN15: =COUNTIFS(G15:BM15,"x") -> 1 | CT15: =COUNTIF(BO15:CS15,"X") -> 0 | DB15: X | DI15: P | DJ15: P | DK15: P | DL15: P | ER15: P | ES15: P | ET15: P | EY15: P | FF15: X | FG15: P | FH15: P | FI15: P | GA15: ? | HF15: X | HG15: X | HH15: X | HI15: X | HJ15: X | HK15: P | HL15: P | HM15: X | HN15: X | HO15: X | HP15: X | HQ15: X | HR15: P | HS15: P | JU15: x | KX15: x | KY15: x | KZ15: x | LA15: x | LB15: x | LC15: x | LD15: x | LE15: x | LF15: x | MZ15: x | NA15: x | NB15: x | NC15: x | ND15: x | NE15: x | NF15: x | NG15: x | NH15: x | NI15: x | NJ15: x | NK15: x | NL15: jan 8 indul
A16: Dalanics Zsolt | B16: 35 | C16: =COUNTIF(F16:DX16,"x") -> 6 | D16: 10 | E16: =COUNTIF(JU16:NI16,"x") -> 3 | F16: =+B16-D16-E16 -> 22 | AH16: x | AZ16: x | BA16: x | BN16: =COUNTIFS(G16:BM16,"x") -> 3 | BO16: X | CF16: X | CT16: =COUNTIF(BO16:CS16,"X") -> 2 | CU16: X | DZ16: P | HC16: X | HN16: X | HX16: X | IA16: X | NB16: x | NC16: x | ND16: x | NH16: Szilveszterre ki tud menni
A17: Dallos Zoltán János | B17: 30 | C17: =COUNTIF(F17:DX17,"x") -> 5 | D17: 14 | E17: =COUNTIF(JU17:NI17,"x") -> 6 | F17: =+B17-D17-E17 -> 10 | AG17: B | AH17: B | AI17: B | AJ17: B | AK17: B | AL17: B | AM17: B | AN17: B | AU17: x | BI17: x | BN17: =COUNTIFS(G17:BM17,"x") -> 2 | BQ17: P | BX17: P | CE17: X | CF17: X | CT17: =COUNTIF(BO17:CS17,"X") -> 2 | DP17: X | FB17: ESTE | FF17: X | FG17: P | FH17: P | FI17: P | GA17: x | GV17: P | GW17: P | GX17: P | GY17: DU | IA17: X | IB17: X | IC17: X | ID17: X | IE17: X | IF17: P | IG17: P | IH17: X | MZ17: X | NA17: X | NB17: P | NC17: P | ND17: P | NE17: X | NF17: X | NG17: X | NH17: X | NI17: P | NJ17: indulás
A18: Dénes Gábor | B18: 22 | C18: =COUNTIF(F18:DX18,"x") -> 7 | D18: 22 | E18: =COUNTIF(JU18:NI18,"x") -> 10 | F18: =+B18-D18-E18 -> -10 | I18: X | J18: X | AR18: x | BN18: =COUNTIFS(G18:BM18,"x") -> 3 | CF18: P | CT18: =COUNTIF(BO18:CS18,"X") -> 0 | CU18: p | CX18: P | DK18: P | DL18: P | DM18: X | DN18: X | DO18: X | DP18: X | DQ18: P | DR18: P | EG18: X | EH18: X | FL18: P | FW18: X | GD18: X | GE18: X | GF18: X | GZ18: X | HE18: P | HF18: X | HG18: X | HH18: X | HI18: X | HJ18: X | HK18: P | HL18: P | HM18: X | HN18: X | HO18: X | HP18: X | HQ18: X | HR18: P | HS18: P | IA18: P | JF18: P | JG18: P | JU18: P | LX18: ADR | LY18: ADR | LZ18: ADR | MZ18: x | NA18: x | NB18: x | NC18: x | ND18: x | NE18: x | NF18: x | NG18: x | NH18: x | NI18: x | NJ18: x | NK18: x | NL18: x | NM18: x | NN18: x | NO18: x | NP18: 01.08-ig
A19: Desics László | B19: 30 | C19: =COUNTIF(F19:DX19,"x") -> 17 | D19: 23 | E19: =COUNTIF(JU19:NI19,"x") -> 8 | F19: =+B19-D19-E19 -> -1 | I19: x | J19: x | K19: x | L19: x | M19: x | P19: x | Q19: x | R19: x | S19: x | T19: B | W19: B | X19: B | Y19: B | Z19: B | AA19: B | AL19: x | AM19: x | BF19: x | BN19: =COUNTIFS(G19:BM19,"x") -> 12 | BV19: P | BW19: P | BX19: P | CE19: X | CF19: X | CT19: =COUNTIF(BO19:CS19,"X") -> 2 | DM19: X | DN19: X | DW19: X | DX19: INDUL | FP19: X | GH19: hozd haza szombatra mindenképp | GK19: H du tud indulni | HD19: P | HE19: P | HF19: x | HG19: x | HH19: x | HI19: x | HJ19: x | HK19: x | HL19: x | HM19: este már tud | HT19: X | IH19: x | IV19: X | NB19: x | NC19: x | ND19: x | NE19: x | NF19: x | NG19: x | NH19: x | NI19: x | NJ19: x | NK19: x | NL19: indulás
A20: Drozd Péter | B20: 30 | C20: =COUNTIF(F20:DX20,"x") -> 12 | D20: 26 | E20: =COUNTIF(JU20:NI20,"x") -> 5 | F20: =+B20-D20-E20 -> -1 | I20: X | J20: x | P20: x | Q20: x | W20: x | AL20: x | AR20: x | BM20: x | BN20: =COUNTIFS(G20:BM20,"x") -> 8 | CB20: P | CC20: P | CD20: P | CE20: P | CF20: P | CT20: =COUNTIF(BO20:CS20,"X") -> 0 | DK20: P | DL20: P | DM20: X | DN20: X | DO20: X | DP20: X | DZ20: P | EN20: P | FB20: P | FP20: X | GD20: X | GY20: X | GZ20: X | HA20: X | HB20: X | HC20: X | HD20: P | HE20: P | HF20: X | HG20: X | HH20: X | HI20: X | HJ20: X | HK20: P | HL20: P | IO20: P | NB20: P | NC20: P | ND20: P | NE20: X | NF20: X | NG20: X | NH20: X | NI20: x | NJ20: x | NK20: x | NL20: x | NM20: x | NN20: x | NO20: x
